<?xml version="1.0"?>
<mujoco model="go2">
  <compiler angle="radian" coordinate="local" inertiafromgeom="true" />
  
  <option timestep="0.002" iterations="50" solver="Newton" tolerance="1e-10" />
  
  <default>
    <joint armature="0.01" damping="0.1" limited="true" />
    <geom conaffinity="0" condim="3" density="5.0" friction="0.8 0.1 0.1" margin="0.01" rgba="0.8 0.6 0.4 1" />
  </default>
  
  <asset>
    <texture type="skybox" builtin="gradient" rgb1="0.4 0.5 0.6" rgb2="0 0 0" width="100" height="100" />
    <texture name="texplane" type="2d" builtin="checker" rgb1="0.2 0.3 0.4" rgb2="0.1 0.2 0.3" width="100" height="100" />
    <material name="matplane" texture="texplane" texrepeat="1 1" texuniform="true" reflectance="0.2" />
  </asset>
  
  <worldbody>
    <!-- Ground plane -->
    <geom name="floor" pos="0 0 0" size="0 0 0.05" type="plane" material="matplane" condim="3" />
    
    <!-- Lighting -->
    <light directional="true" diffuse=".8 .8 .8" specular=".1 .1 .1" pos="0 0 1" dir="0 0 -1" />
    
    <!-- Sites for sensors -->
    <site name="trunk_vel" pos="0 0 0" size="0.01" rgba="1 0 0 0" />
    <site name="trunk_gyro" pos="0 0 0" size="0.01" rgba="0 1 0 0" />
    
    <!-- Floating base -->
    <body name="trunk" pos="0 0 0.42" quat="1 0 0 0">
      <!-- Main body (trunk) with proper floating base (6 DOF) -->
      <freejoint name="root" />
      
      <geom name="trunk" type="box" size="0.2 0.1 0.05" pos="0 0 0" rgba="0.2 0.2 0.2 1" />
      
      <!-- Attach sites to trunk for sensors -->
      <site name="trunk_vel_site" pos="0 0 0" size="0.01" />
      <site name="trunk_gyro_site" pos="0 0 0" size="0.01" />
      
      <!-- Front Right Leg -->
      <body name="FR_hip" pos="0.18 -0.075 0">
        <joint name="FR_hip_joint" type="hinge" axis="0 0 1" range="-0.7 0.7" />
        <geom name="FR_hip" type="cylinder" size="0.02 0.02" pos="0 0 0" rgba="0.4 0.4 0.4 1" />
        
        <body name="FR_thigh" pos="0 -0.05 0">
          <joint name="FR_thigh_joint" type="hinge" axis="1 0 0" range="0.0 2.8" />
          <geom name="FR_thigh" type="capsule" size="0.02" fromto="0 0 0 0 0 -0.12" rgba="0.3 0.3 0.3 1" />
          
          <body name="FR_calf" pos="0 0 -0.12">
            <joint name="FR_calf_joint" type="hinge" axis="1 0 0" range="-3.0 -0.2" />
            <geom name="FR_calf" type="capsule" size="0.015" fromto="0 0 0 0 0 -0.12" rgba="0.25 0.25 0.25 1" />
            <geom name="FR_foot" type="sphere" size="0.02" pos="0 0 -0.12" rgba="0.4 0.4 0.4 1" />
          </body>
        </body>
      </body>
      
      <!-- Front Left Leg -->
      <body name="FL_hip" pos="0.18 0.075 0">
        <joint name="FL_hip_joint" type="hinge" axis="0 0 1" range="-0.7 0.7" />
        <geom name="FL_hip" type="cylinder" size="0.02 0.02" pos="0 0 0" rgba="0.4 0.4 0.4 1" />
        
        <body name="FL_thigh" pos="0 0.05 0">
          <joint name="FL_thigh_joint" type="hinge" axis="1 0 0" range="0.0 2.8" />
          <geom name="FL_thigh" type="capsule" size="0.02" fromto="0 0 0 0 0 -0.12" rgba="0.3 0.3 0.3 1" />
          
          <body name="FL_calf" pos="0 0 -0.12">
            <joint name="FL_calf_joint" type="hinge" axis="1 0 0" range="-3.0 -0.2" />
            <geom name="FL_calf" type="capsule" size="0.015" fromto="0 0 0 0 0 -0.12" rgba="0.25 0.25 0.25 1" />
            <geom name="FL_foot" type="sphere" size="0.02" pos="0 0 -0.12" rgba="0.4 0.4 0.4 1" />
          </body>
        </body>
      </body>
      
      <!-- Rear Right Leg -->
      <body name="RR_hip" pos="-0.18 -0.075 0">
        <joint name="RR_hip_joint" type="hinge" axis="0 0 1" range="-0.7 0.7" />
        <geom name="RR_hip" type="cylinder" size="0.02 0.02" pos="0 0 0" rgba="0.4 0.4 0.4 1" />
        
        <body name="RR_thigh" pos="0 -0.05 0">
          <joint name="RR_thigh_joint" type="hinge" axis="1 0 0" range="0.0 2.8" />
          <geom name="RR_thigh" type="capsule" size="0.02" fromto="0 0 0 0 0 -0.12" rgba="0.3 0.3 0.3 1" />
          
          <body name="RR_calf" pos="0 0 -0.12">
            <joint name="RR_calf_joint" type="hinge" axis="1 0 0" range="-3.0 -0.2" />
            <geom name="RR_calf" type="capsule" size="0.015" fromto="0 0 0 0 0 -0.12" rgba="0.25 0.25 0.25 1" />
            <geom name="RR_foot" type="sphere" size="0.02" pos="0 0 -0.12" rgba="0.4 0.4 0.4 1" />
          </body>
        </body>
      </body>
      
      <!-- Rear Left Leg -->
      <body name="RL_hip" pos="-0.18 0.075 0">
        <joint name="RL_hip_joint" type="hinge" axis="0 0 1" range="-0.7 0.7" />
        <geom name="RL_hip" type="cylinder" size="0.02 0.02" pos="0 0 0" rgba="0.4 0.4 0.4 1" />
        
        <body name="RL_thigh" pos="0 0.05 0">
          <joint name="RL_thigh_joint" type="hinge" axis="1 0 0" range="0.0 2.8" />
          <geom name="RL_thigh" type="capsule" size="0.02" fromto="0 0 0 0 0 -0.12" rgba="0.3 0.3 0.3 1" />
          
          <body name="RL_calf" pos="0 0 -0.12">
            <joint name="RL_calf_joint" type="hinge" axis="1 0 0" range="-3.0 -0.2" />
            <geom name="RL_calf" type="capsule" size="0.015" fromto="0 0 0 0 0 -0.12" rgba="0.25 0.25 0.25 1" />
            <geom name="RL_foot" type="sphere" size="0.02" pos="0 0 -0.12" rgba="0.4 0.4 0.4 1" />
          </body>
        </body>
      </body>
    </body>
  </worldbody>
  
  <actuator>
    <!-- Motor actuators with limits -->
    <motor name="FR_hip_motor" joint="FR_hip_joint" gear="35" ctrllimited="true" ctrlrange="-1.0 1.0" />
    <motor name="FR_thigh_motor" joint="FR_thigh_joint" gear="35" ctrllimited="true" ctrlrange="-1.0 1.0" />
    <motor name="FR_calf_motor" joint="FR_calf_joint" gear="35" ctrllimited="true" ctrlrange="-1.0 1.0" />
    
    <motor name="FL_hip_motor" joint="FL_hip_joint" gear="35" ctrllimited="true" ctrlrange="-1.0 1.0" />
    <motor name="FL_thigh_motor" joint="FL_thigh_joint" gear="35" ctrllimited="true" ctrlrange="-1.0 1.0" />
    <motor name="FL_calf_motor" joint="FL_calf_joint" gear="35" ctrllimited="true" ctrlrange="-1.0 1.0" />
    
    <motor name="RR_hip_motor" joint="RR_hip_joint" gear="35" ctrllimited="true" ctrlrange="-1.0 1.0" />
    <motor name="RR_thigh_motor" joint="RR_thigh_joint" gear="35" ctrllimited="true" ctrlrange="-1.0 1.0" />
    <motor name="RR_calf_motor" joint="RR_calf_joint" gear="35" ctrllimited="true" ctrlrange="-1.0 1.0" />
    
    <motor name="RL_hip_motor" joint="RL_hip_joint" gear="35" ctrllimited="true" ctrlrange="-1.0 1.0" />
    <motor name="RL_thigh_motor" joint="RL_thigh_joint" gear="35" ctrllimited="true" ctrlrange="-1.0 1.0" />
    <motor name="RL_calf_motor" joint="RL_calf_joint" gear="35" ctrllimited="true" ctrlrange="-1.0 1.0" />
  </actuator>
  
  <sensor>
    <!-- Velocity sensors for observation space -->
    <velocimeter name="trunk_linear_velocity" site="trunk_vel_site" />
    <gyro name="trunk_angular_velocity" site="trunk_gyro_site" />
  </sensor>
</mujoco> 